Workbook
Name Slicer_Rank: #N/A

Sheet dashboard
D5: Total Deaths (2001-2021)\Per Cause
B8: Ages: 1-14 in 5-year groups; 15-65+ in 10-year groups | G8: Cause of Deaths | H8: Crude Rate/1000 population | I8: Death % Per Year
B9: Ethnicity: All Ethnicities | G9: =Analyze!A20 -> Heart Disease | H9: =Analyze!B20 -> 153.62 | I9: =Analyze!C20 -> 0.1334
B10: Geographies: United States | G10: =Analyze!A25 -> Malignant Neoplasms | H10: =Analyze!B25 -> 135.89 | I10: =Analyze!C25 -> 0.1603
B11: Intent: All Deaths with drilldown to ICD codes | G11: =Analyze!A10 -> Alzheimer's Disease | H11: =Analyze!B10 -> 123.55 | I11: =Analyze!C10 -> 0.0545
B12: Number: 10 | G12: =Analyze!A18 -> Covid-19 | H12: =Analyze!B18 -> 94.9 | I12: =Analyze!C18 -> 0.1084
B13: Race: All Races | G13: =Analyze!A33 -> Short Gestation | H13: =Analyze!B33 -> 82.6 | I13: =Analyze!C33 -> 0.223
B14: RaceYear: 2001 - 2021 with No Race | G14: =Analyze!A28 -> Parkinson's Disease | H14: =Analyze!B28 -> 67.3 | I14: =Analyze!C28 -> 0.02
B15: Sexes: Males, Females | G15: =Analyze!A36 -> Unintentional Injury | H15: =Analyze!B36 -> 54.245455 | I15: =Analyze!C36 -> 0.28054545
G16: =Analyze!A14 -> Chronic Low. Respiratory Disease | H16: =Analyze!B14 -> 51.25 | I16: =Analyze!C14 -> 0.038166667
G17: =Analyze!A27 -> Nephritis | H17: =Analyze!B27 -> 47.6 | I17: =Analyze!C27 -> 0.022
B18: Total Deaths (2001-2021)\Per Age Range | G18: =Analyze!A34 -> Sids | H18: =Analyze!B34 -> 40.9 | I18: =Analyze!C34 -> 0.111
G19: =Analyze!A13 -> Cerebrovascular | H19: =Analyze!B13 -> 35.44 | I19: =Analyze!C13 -> 0.0304
G20: =Analyze!A26 -> Maternal Pregnancy Comp. | H20: =Analyze!B26 -> 31.2 | I20: =Analyze!C26 -> 0.084
G21: =Analyze!A19 -> Diabetes Mellitus | H21: =Analyze!B19 -> 29.2 | I21: =Analyze!C19 -> 0.03025
G22: =Analyze!A17 -> Congenital Anomalies | H22: =Analyze!B17 -> 23.3 | I22: =Analyze!C17 -> 0.125
G23: =Analyze!A24 -> Liver Disease | H23: =Analyze!B24 -> 20.3 | I23: =Analyze!C24 -> 0.0424
G24: =Analyze!A30 -> Placenta Cord Membranes | H24: =Analyze!B30 -> 18.9 | I24: =Analyze!C30 -> 0.051
G25: =Analyze!A11 -> Bacterial Sepsis | H25: =Analyze!B11 -> 15.6 | I25: =Analyze!C11 -> 0.042
G26: =Analyze!A35 -> Suicide | H26: =Analyze!B35 -> 15.133333 | I26: =Analyze!C35 -> 0.11266667
G27: =Analyze!A31 -> Respiratory Distress | H27: =Analyze!B31 -> 11.6 | I27: =Analyze!C31 -> 0.031
G28: =Analyze!A15 -> Circulatory System Disease | H28: =Analyze!B15 -> 11.3 | I28: =Analyze!C15 -> 0.03
G29: =Analyze!A23 -> Intrauterine Hypoxia | H29: =Analyze!B23 -> 10 | I29: =Analyze!C23 -> 0.027
G30: =Analyze!A21 -> Homicide | H30: =Analyze!B21 -> 7.7571429 | I30: =Analyze!C21 -> 0.099285714
G31: =Analyze!A32 -> Septicemia | H31: =Analyze!B32 -> 5.9333333 | I31: =Analyze!C32 -> 0.014666667
G32: =Analyze!A16 -> Complicated Pregnancy | H32: =Analyze!B16 -> 1.15 | I32: =Analyze!C16 -> 0.0085
G33: =Analyze!A29 -> Perinatal Period | H33: =Analyze!B29 -> 0.4 | I33: =Analyze!C29 -> 0.025
G34: =Analyze!A22 -> Influenza & Pneumonia | H34: =Analyze!B22 -> 0.2 | I34: =Analyze!C22 -> 0.0165
G35: =Analyze!A12 -> Benign Neoplasms | H35: =Analyze!B12 -> 0.2 | I35: =Analyze!C12 -> 0.014

Sheet Analyze
A3: Max of Deaths | B3: Min of Deaths | C3: Average of Deaths2 | D3: Average of Crude Rate | E3: Average of Percentage
A4: 695547 | B4: 27 | C4: 47718.664 | D4: 57.747273 | E4: 0.099954545
A9: Row Labels | B9: Average of Crude Rate | C9: Average of Percentage | D9: Sum of Deaths
A10: Alzheimer's Disease | B10: 123.55 | C10: 0.0545 | D10: 237321 | E10: =A10 -> Alzheimer's Disease | F10: =B10 -> 123.55 | G10: =C10 -> 0.0545 | H10: =D10 -> 237321
A11: Bacterial Sepsis | B11: 15.6 | C11: 0.042 | D11: 557 | E11: =A11 -> Bacterial Sepsis | F11: =B11 -> 15.6 | G11: =C11 -> 0.042 | H11: =D11 -> 557
A12: Benign Neoplasms | B12: 0.2 | C12: 0.014 | D12: 37 | E12: =A12 -> Benign Neoplasms | F12: =B12 -> 0.2 | G12: =C12 -> 0.014 | H12: =D12 -> 37
A13: Cerebrovascular | B13: 35.44 | C13: 0.0304 | D13: 325682 | E13: =A13 -> Cerebrovascular | F13: =B13 -> 35.44 | G13: =C13 -> 0.0304 | H13: =D13 -> 325682
A14: Chronic Low. Respiratory Disease | B14: 51.25 | C14: 0.038166667 | D14: 283387 | E14: =A14 -> Chronic Low. Respiratory Disease | F14: =B14 -> 51.25 | G14: =C14 -> 0.038166667 | H14: =D14 -> 283387
A15: Circulatory System Disease | B15: 11.3 | C15: 0.03 | D15: 402 | E15: =A15 -> Circulatory System Disease | F15: =B15 -> 11.3 | G15: =C15 -> 0.03 | H15: =D15 -> 402
A16: Complicated Pregnancy | B16: 1.15 | C16: 0.0085 | D16: 1011 | E16: =A16 -> Complicated Pregnancy | F16: =B16 -> 1.15 | G16: =C16 -> 0.0085 | H16: =D16 -> 1011
A17: Congenital Anomalies | B17: 23.3 | C17: 0.125 | D17: 5144 | E17: =A17 -> Congenital Anomalies | F17: =B17 -> 23.3 | G17: =C17 -> 0.125 | H17: =D17 -> 5144
A18: Covid-19 | B18: 94.9 | C18: 0.1084 | D18: 833692 | E18: =A18 -> Covid-19 | F18: =B18 -> 94.9 | G18: =C18 -> 0.1084 | H18: =D18 -> 833692
A19: Diabetes Mellitus | B19: 29.2 | C19: 0.03025 | D19: 206575 | E19: =A19 -> Diabetes Mellitus | F19: =B19 -> 29.2 | G19: =C19 -> 0.03025 | H19: =D19 -> 206575
A20: Heart Disease | B20: 153.62 | C20: 0.1334 | D20: 1390805 | E20: =A20 -> Heart Disease | F20: =B20 -> 153.62 | G20: =C20 -> 0.1334 | H20: =D20 -> 1390805
A21: Homicide | B21: 7.7571429 | C21: 0.099285714 | D21: 22632 | E21: =A21 -> Homicide | F21: =B21 -> 7.7571429 | G21: =C21 -> 0.099285714 | H21: =D21 -> 22632
... A36: Unintentional Injury | B36: 54.245455 | C36: 0.28054545 | D36: 449851 | E36: =A36 -> Unintentional Injury | F36: =B36 -> 54.245455 | G36: =C36 -> 0.28054545 | H36: =D36 -> 449851
A37: Grand Total | B37: 57.747273 | C37: 0.099954545 | D37: 5249053
A42: Age Group | B42: Sum of Deaths | C42: Age Group | D42: Total Deaths
A43: Less than 1yrs | B43: 13190 | C43: =A43 -> Less than 1yrs | D43: =B43 -> 13190
A44: 1 to 4 yrs | B44: 2679 | C44: =A44 -> 1 to 4 yrs | D44: =B44 -> 2679
A45: 5 to 9 yrs | B45: 1806 | C45: =A45 -> 5 to 9 yrs | D45: =B45 -> 1806
A46: 10 to 14 yrs | B46: 2787 | C46: =A46 -> 10 to 14 yrs | D46: =B46 -> 2787
A47: 15 to 24 yrs | B47: 33791 | C47: =A47 -> 15 to 24 yrs | D47: =B47 -> 33791
A48: 25 to 34 yrs | B48: 69327 | C48: =A48 -> 25 to 34 yrs | D48: =B48 -> 69327
A49: 35 to 44 yrs | B49: 101214 | C49: =A49 -> 35 to 44 yrs | D49: =B49 -> 101214
A50: 45 to 54 yrs | B50: 173586 | C50: =A50 -> 45 to 54 yrs | D50: =B50 -> 173586
A51: 55 to 64 yrs | B51: 386826 | C51: =A51 -> 55 to 64 yrs | D51: =B51 -> 386826
A52: 65 above | B52: 1882391 | C52: =A52 -> 65 above | D52: =B52 -> 1882391
A53: All Ages | B53: 2581456 | C53: =A53 -> All Ages | D53: =B53 -> 2581456
A54: Grand Total | B54: 5249053

Sheet deaths_Table
A1: Leading cause of death
B3: Age Group | C3: Rank | D3: Cause Category | E3: Deaths | F3: Crude Rate | G3: Percentage | K3: Ages: 1-14 in 5-year groups; 15-65+ in 10-year groups
B4: Less than 1yrs | C4: 1 | D4: Congenital Anomalies | E4: 3963 | F4: 111.2 | G4: 0.3 | K4: Ethnicity: All Ethnicities
B5: Less than 1yrs | C5: 2 | D5: Short Gestation | E5: 2946 | F5: 82.6 | G5: 0.223 | K5: Geographies: United States
B6: Less than 1yrs | C6: 3 | D6: Sids | E6: 1459 | F6: 40.9 | G6: 0.111 | K6: Intent: All Deaths with drilldown to ICD codes
B7: Less than 1yrs | C7: 4 | D7: Unintentional Injury | E7: 1306 | F7: 36.6 | G7: 0.099 | K7: Number: 10
B8: Less than 1yrs | C8: 5 | D8: Maternal Pregnancy Comp. | E8: 1113 | F8: 31.2 | G8: 0.084 | K8: Race: All Races
B9: Less than 1yrs | C9: 6 | D9: Placenta Cord Membranes | E9: 672 | F9: 18.9 | G9: 0.051 | K9: RaceYear: 2001 - 2021 with No Race
B10: Less than 1yrs | C10: 7 | D10: Bacterial Sepsis | E10: 557 | F10: 15.6 | G10: 0.042 | K10: Sexes: Males, Females
B11: Less than 1yrs | C11: 8 | D11: Respiratory Distress | E11: 414 | F11: 11.6 | G11: 0.031 | K11: Years: 2021
B12: Less than 1yrs | C12: 9 | D12: Circulatory System Disease | E12: 402 | F12: 11.3 | G12: 0.03 | K12: ** indicates Unstable values, -- indicates Suppressed values, --* indicates Secondary Suppression
B13: Less than 1yrs | C13: 10 | D13: Intrauterine Hypoxia | E13: 358 | F13: 10 | G13: 0.027 | K13: Produced by: National Center for Injury Prevention and Control, CDC.
B14: 1 to 4 yrs | C14: 1 | D14: Unintentional Injury | E14: 1299 | F14: 8.5 | G14: 0.485
B15: 1 to 4 yrs | C15: 2 | D15: Congenital Anomalies | E15: 412 | F15: 2.7 | G15: 0.154
B16: 1 to 4 yrs | C16: 3 | D16: Homicide | E16: 309 | F16: 2 | G16: 0.115
B17: 1 to 4 yrs | C17: 4 | D17: Malignant Neoplasms | E17: 282 | F17: 1.8 | G17: 0.105 | K17: top common cause of deaths
B18: 1 to 4 yrs | C18: 5 | D18: Heart Disease | E18: 116 | F18: 0.8 | G18: 0.043 | K18: Max Deaths
B19: 1 to 4 yrs | C19: 6 | D19: Perinatal Period | E19: 68 | F19: 0.4 | G19: 0.025 | K19: Min Deaths
B20: 1 to 4 yrs | C20: 7 | D20: Cerebrovascular | E20: 55 | F20: 0.4 | G20: 0.021 | K20: Average deaths
B21: 1 to 4 yrs | C21: 8 | D21: Covid-19 | E21: 54 | F21: 0.4 | G21: 0.02 | K21: most deaths in per age
B22: 1 to 4 yrs | C22: 9 | D22: Influenza & Pneumonia | E22: 47 | F22: 0.3 | G22: 0.018 | K22: Deaths per 1000
B23: 1 to 4 yrs | C23: 10 | D23: Benign Neoplasms | E23: 37 | F23: 0.2 | G23: 0.014
B24: 10 to 14 yrs | C24: 1 | D24: Unintentional Injury | E24: 915 | F24: 4.3 | G24: 0.328
B25: 10 to 14 yrs | C25: 2 | D25: Suicide | E25: 598 | F25: 2.8 | G25: 0.215
B26: 10 to 14 yrs | C26: 3 | D26: Malignant Neoplasms | E26: 449 | F26: 2.1 | G26: 0.161
B27: 10 to 14 yrs | C27: 4 | D27: Homicide | E27: 298 | F27: 1.4 | G27: 0.107
B28: 10 to 14 yrs | C28: 5 | D28: Congenital Anomalies | E28: 179 | F28: 0.8 | G28: 0.064
B29: 10 to 14 yrs | C29: 6 | D29: Heart Disease | E29: 132 | F29: 0.6 | G29: 0.047
B30: 10 to 14 yrs | C30: 7 | D30: Covid-19 | E30: 79 | F30: 0.4 | G30: 0.028
B31: 10 to 14 yrs | C31: 8 | D31: Cerebrovascular | E31: 53 | F31: 0.2 | G31: 0.019
B32: 10 to 14 yrs | C32: 9 | D32: Chronic Low. Respiratory Disease | E32: 45 | F32: 0.2 | G32: 0.016
B33: 10 to 14 yrs | C33: 10 | D33: Diabetes Mellitus | E33: 39 | F33: 0.2 | G33: 0.014
B34: 15 to 24 yrs | C34: 1 | D34: Unintentional Injury | E34: 15792 | F34: 36.7 | G34: 0.467
... B113: All Ages | C113: 10 | D113: Nephritis | E113: 54358 | F113: 16.4 | G113: 0.021

Sheet lcd-table_for_clean
A1: Age Group | B1: Rank | C1: Cause Category | D1: Deaths | E1: Crude Rate | F1: Percentage
A2: <1 | B2: 1 | C2: Congenital Anomalies | D2: 3963 | E2: 111.2 | F2: 0.3
A3: <1 | B3: 2 | C3: Short Gestation | D3: 2946 | E3: 82.6 | F3: 0.223
A4: <1 | B4: 3 | C4: Sids | D4: 1459 | E4: 40.9 | F4: 0.111
A5: <1 | B5: 4 | C5: Unintentional Injury | D5: 1306 | E5: 36.6 | F5: 0.099
A6: <1 | B6: 5 | C6: Maternal Pregnancy Comp. | D6: 1113 | E6: 31.2 | F6: 0.084
A7: <1 | B7: 6 | C7: Placenta Cord Membranes | D7: 672 | E7: 18.9 | F7: 0.051
A8: <1 | B8: 7 | C8: Bacterial Sepsis | D8: 557 | E8: 15.6 | F8: 0.042
A9: <1 | B9: 8 | C9: Respiratory Distress | D9: 414 | E9: 11.6 | F9: 0.031
A10: <1 | B10: 9 | C10: Circulatory System Disease | D10: 402 | E10: 11.3 | F10: 0.03
A11: <1 | B11: 10 | C11: Intrauterine Hypoxia | D11: 358 | E11: 10 | F11: 0.027
A12: 45383 | B12: 1 | C12: Unintentional Injury | D12: 1299 | E12: 8.5 | F12: 0.485
A13: 45383 | B13: 2 | C13: Congenital Anomalies | D13: 412 | E13: 2.7 | F13: 0.154
A14: 45383 | B14: 3 | C14: Homicide | D14: 309 | E14: 2 | F14: 0.115
A15: 45383 | B15: 4 | C15: Malignant Neoplasms | D15: 282 | E15: 1.8 | F15: 0.105
A16: 45383 | B16: 5 | C16: Heart Disease | D16: 116 | E16: 0.8 | F16: 0.043
A17: 45383 | B17: 6 | C17: Perinatal Period | D17: 68 | E17: 0.4 | F17: 0.025
A18: 45383 | B18: 7 | C18: Cerebrovascular | D18: 55 | E18: 0.4 | F18: 0.021
A19: 45383 | B19: 8 | C19: Covid-19 | D19: 54 | E19: 0.4 | F19: 0.02
A20: 45383 | B20: 9 | C20: Influenza & Pneumonia | D20: 47 | E20: 0.3 | F20: 0.018
A21: 45383 | B21: 10 | C21: Benign Neoplasms | D21: 37 | E21: 0.2 | F21: 0.014
A22: 41913 | B22: 1 | C22: Unintentional Injury | D22: 915 | E22: 4.3 | F22: 0.328
A23: 41913 | B23: 2 | C23: Suicide | D23: 598 | E23: 2.8 | F23: 0.215
... A31: 41913 | B31: 10 | C31: Diabetes Mellitus | D31: 39 | E31: 0.2 | F31: 0.014
A32: 15-24 | B32: 1 | C32: Unintentional Injury | D32: 15792 | E32: 36.7 | F32: 0.467
A33: 15-24 | B33: 2 | C33: Homicide | D33: 6635 | E33: 15.4 | F33: 0.196
A34: 15-24 | B34: 3 | C34: Suicide | D34: 6528 | E34: 15.2 | F34: 0.193
A35: 15-24 | B35: 4 | C35: Covid-19 | D35: 1401 | E35: 3.3 | F35: 0.041
A36: 15-24 | B36: 5 | C36: Malignant Neoplasms | D36: 1323 | E36: 3.1 | F36: 0.039
A37: 15-24 | B37: 6 | C37: Heart Disease | D37: 944 | E37: 2.2 | F37: 0.028
A38: 15-24 | B38: 7 | C38: Congenital Anomalies | D38: 419 | E38: 1 | F38: 0.012
A39: 15-24 | B39: 8 | C39: Diabetes Mellitus | D39: 345 | E39: 0.8 | F39: 0.01
A40: 15-24 | B40: 9 | C40: Complicated Pregnancy | D40: 214 | E40: 0.5 | F40: 0.006
A41: 15-24 | B41: 10 | C41: Cerebrovascular | D41: 190 | E41: 0.4 | F41: 0.006
A42: 25-34 | B42: 1 | C42: Unintentional Injury | D42: 34452 | E42: 75.7 | F42: 0.497
A43: 25-34 | B43: 2 | C43: Suicide | D43: 8862 | E43: 19.5 | F43: 0.128
... A71: 45-54 | B71: 10 | C71: Homicide | D71: 2768 | E71: 6.8 | F71: 0.016
A72: 45540 | B72: 1 | C72: Unintentional Injury | D72: 827 | E72: 4.1 | F72: 0.458
A73: 45540 | B73: 2 | C73: Malignant Neoplasms | D73: 347 | E73: 1.7 | F73: 0.192
A74: 45540 | B74: 3 | C74: Homicide | D74: 188 | E74: 0.9 | F74: 0.104
...
